Workbook

Sheet Income statement 
A1: JP Morgan
A2: 2024 Income Statement
A3: (In millons)
B5: 2024 | D5: % of Total Sales
A6: Sales | C6: 2361 | D6: =C6/$C$6 -> 1
A7: Cost of goods sold | C7: 1344 | D7: =C7/$C$6 -> 0.56925032
A8: Depreciation | C8: 276 | D8: =C8/$C$6 -> 0.11689962
A9: Earnings before interest and taxes | C9: =C6-C7-C8 -> 741 | D9: =C9/$C$6 -> 0.31385006
A10: Interest paid | C10: 141 | D10: =C10/$C$6 -> 0.059720457
A11: Taxable income | C11: =C9-C10 -> 600 | D11: =C11/$C$6 -> 0.25412961
A12: Taxes (21%) | C12: =C11*0.21 -> 126 | D12: =C12/$C$6 -> 0.053367217
A13: Net income | C13: =C11-C12 -> 474 | D13: =C13/$C$6 -> 0.20076239
A14: Dividends | C14: 158 | D14: =C14/$C$6 -> 0.066920796
A15: Addition to retained earnings | C15: =C13-C14 -> 316 | D15: =C15/$C$6 -> 0.13384159

Sheet Balance Sheet
A3: JP Morgan Chase | H3: Assets = Liabilities + Stockholders Equity
A4: Balance sheet as of December 31, 2024
A5: (in millions)
B7: 2023 | C7: % of Total Assets | D7: 2024 | E7: % of Total Assets | F7: Change
A8: Assets
A9: Current Assets
A10: Cash | B10: 84 | C10: =B10/$B$16 -> 0.024903647 | D10: 98 | E10: =D10/$D$16 -> 0.026997245 | F10: =E10-C10 -> 0.0020935986
A11: Accounts Receivable | B11: 165 | C11: =B11/$B$16 -> 0.048917877 | D11: 188 | E11: =D11/$D$16 -> 0.051790634 | F11: =E11-C11 -> 0.0028727563
A12: Inventory | B12: 393 | C12: =B12/$B$16 -> 0.11651349 | D12: 422 | E12: =D12/$D$16 -> 0.11625344 | F12: =E12-C12 -> -0.00026004595
A13: Total | B13: =SUM(B10:B12) -> 642 | C13: =B13/$B$16 -> 0.19033501 | D13: =SUM(D10:D12) -> 708 | E13: =D13/$D$16 -> 0.19504132 | F13: =E13-C13 -> 0.004706309
A14: Fixed Assets
A15: Net Plant and Equipment | B15: 2731 | C15: =B15/$B$16 -> 0.80966499 | D15: 2922 | E15: =D15/$D$16 -> 0.80495868 | F15: =E15-C15 -> -0.004706309
A16: Total Assets | B16: =B13+B15 -> 3373 | C16: =B16/$B$16 -> 1 | D16: =D13+D15 -> 3630 | E16: =D16/$D$16 -> 1 | F16: =E16-C16 -> 0
A18: Liabilities and Owners Equity
A19: Current liabilities
A20: Accounts payable | B20: 312 | C20: =B20/$B$16 -> 0.092499259 | D20: 344 | E20: =D20/$D$16 -> 0.09476584 | F20: =E20-C20 -> 0.0022665814
A21: Notes payable | B21: 231 | C21: =B21/$B$16 -> 0.068485028 | D21: 204 | E21: =D21/$D$16 -> 0.056198347 | F21: =E21-C21 -> -0.012286681
A22: Total | B22: =B20+B21 -> 543 | C22: =B22/$B$16 -> 0.16098429 | D22: =D20+D21 -> 548 | E22: =D22/$D$16 -> 0.15096419 | F22: =E22-C22 -> -0.0100201
A23: Long-term debt | B23: 531 | C23: =B23/$B$16 -> 0.15742662 | D23: 457 | E23: =D23/$D$16 -> 0.12589532 | F23: =E23-C23 -> -0.031531306
A24: Owners equity
A25: Common stock and Paid-In Surplus | B25: 500 | C25: =B25/$B$16 -> 0.14823599 | D25: 510 | E25: =D25/$D$16 -> 0.14049587 | F25: =E25-C25 -> -0.0077401239
A26: Retained earnings | B26: 1799 | C26: =B26/$B$16 -> 0.5333531 | D26: 2115 | E26: =D26/$D$16 -> 0.58264463 | F26: =E26-C26 -> 0.04929153
A27: Total | B27: =B25+B26 -> 2299 | C27: =B27/$B$16 -> 0.68158909 | D27: =D25+D26 -> 2625 | E27: =D27/$D$16 -> 0.7231405 | F27: =E27-C27 -> 0.041551406
A28: Total Liabilites and Owners Equity | B28: =B27+B22+B23 -> 3373 | C28: =B28/$B$16 -> 1 | D28: =D27+D22+D23 -> 3630 | E28: =D28/$D$16 -> 1 | F28: =E28-C28 -> 0

Sheet Financial Ratios
A1: Financial Ratios. Prufuck Corporation. Year 2022
A2: Interpretations: assuming that Prufruck Corporation is a Chemical (basic) company. The interpretation and the standards found for the ratios if they are either good or bad are based on the information I have pulled from NYU Stern Data website, Full Ratio website, Ready Ratios website, the Corporate Finance Institute, Zycrus, the U.S. Bureau of Labor Statistics, and the Indonesian Stock Exchange. Furthermore, the definitions are based on the class discussions and what was talked between students and the Professor. Besides basing my definitions on other trust worthy sources such as the Essential of Corporate Finance Book and other reputational sources such as Investopedia and the Corporate Finance Institute to provide more insight to the definitions I have generated.
A3: I know that the information I have pulled for the standards might not be the best type of information, mainly because the information is based on the financial statements from publicaly traded companies which are not proportional in dimension to other small companies as can be Prufruck Corporation
A9: Common Financial Ratios | E9: Interpretation | F9: Standard | G9: Links | H9: G/B | I9: Extra Notes
A10: I. Short-Term Solvency (Liquidity) Measures
A12: Current Ratio | E12: Definition: current ratio is a measure of short-term liquidity. The higher the current ratio the better because it indicates liquidity
A13: Current Assets/Current Liabilities | B13: ='Balance Sheet'!D13/'Balance Sheet'!D22 -> 1.2919708 | C13: times | E13: For every 1.290 dollar in current asset there is $1 in liabilities. Average on the industry is 2.17 which makes this ratio being below this number, which is not ideal | F13: Above 2.17 is good | G13: FullRatio | H13: Bad
A15: Quick ratio | E15: Definition: Inventory is often the least liquid current asset. To further evaluate liquidity, the quick ratio is computed like the current ratio, except inventory is omitted
A16: (Current Assets-Inventory)/Current Liabilities | B16: =('Balance Sheet'!D13-'Balance Sheet'!D12)/('Balance Sheet'!D22) -> 0.52189781 | C16: times | E16: For every current asset minus the inventory there is double the liabilities. Average on the industry 1.08 | F16: Above 1.08 is good | G16: FullRatio | H16: Bad
A18: Cash Ratio | E18: Definition: short-term creditors are interested in this one. It is the ability of the company to meet the short-term liabilities by using only cash and other cash equivilants which are the most liquid assets
A19: Cash/Current Liabilities | B19: ='Balance Sheet'!D10/'Balance Sheet'!D22 -> 0.17883212 | C19: times | E19: Cash it is only 17.88% compared to the current liabilities. According to the standard this ratio would be bad because the ideal is not below 0.5 and this one is 0.17 making it fall way behind the number 0.5 | F19: No ideal number, a ratio of not lower than 0.5 to 1 is usually preferred | G19: Corporate Finance Institute | H19: Bad
A21: II. Long-Term Solvency Measures , or financial leverage, ratios
A23: Total debt ratio | E23: Definition: it is the total amount of assets a company has compared to the total amount of liabilities. The reason why you substract Total Equity from Total Assets is to calculate the total number of Total Liabilities considering short-term and long-term on the balance sheet
A24: (Total Assets-Total Equity)/Total Assets | B24: =('Balance Sheet'!D16-'Balance Sheet'!D27)/'Balance Sheet'!D16 -> 0.2768595 | C24: times | E24: The Total Debt Ratio for P Corp is 0.28 in debt for evert dollar in total assets. The average in the industry is set to be 0.49, thefore this ratio is very good for P Corp because it means a smaller amount of liabilities compared to their assents making them a pretty solvent company in the long-term | F24: Average 0.49 | G24: Ready Ratios | H24: Good
A26: Debt equity ratio | E26: Definition: calculates the weight of total debt including long-term and short-term against total shareholders’ equity
A27: Total debt/Total equity | B27: =('Balance Sheet'!D22+'Balance Sheet'!D23)/'Balance Sheet'!D27 -> 0.38285714 | C27: times | E27: The company has 38% of debt compared to the equity. Below the average of industry which means that is good because the use less debt to finance themselves. A higher ratio is associated with risk, howver P Corp is below the risk that this industry holds | F27: Average on the industry 57.99% | G27: NYU | H27: Good
A29: Equity multiplier | E29: Definition: measures the portion of the company’s assets that are financed by equity. This ratio tells us the level of debt financing that a company has used to acquire assets and maintain operations. A higher ratio indicates that a significant portion of the firm assets are financed by debt, howver if it is too low means that the firm is unable to obtain money from leanders or the just avoid the use of debt to acquire assets
A30: Total Assets/Total Equity | B30: ='Balance Sheet'!D16/'Balance Sheet'!D27 -> 1.3828571 | C30: times | E30: For every dollar of equity P Corp has $1.38 in assets. This ratio has its pros and cons for P Corp because it is true that it is lower than the average in the industry which is 1.58 meaning less financial risk and more equity | F30: Average on the industry 1.58 | G30: NYU | H30: Good
A32: Times interest earned ratio | E32: Definition: this ratio is a common measure of long-term solvency. This ratio measures how well a company has its interest obligations covered. Usually the higher the ratio the better
A33: EBIT/Interest | B33: ='Income statement '!C9/'Income statement '!C10 -> 5.2553191 | C33: times | E33: The company makes 5.25 times more the interest the have to pay. The average ratio for the industry is 3.03 . The ratio for P Corp is pretty good compared to the industry, however is also condidered high because a very high ratio is a sign of having cash stopped and not investing it for the growth of the company | F33: Average on the industry 3.03 | G33: NYU | H33: Good
A35: Cash coverage ratio | E35: Definition: used to compare the company’s cash balance to its annual interest expense. This is a very conservative metric, as it compares only cash on hand (no other assets) to the interest expense the company has relative to its debt.
A36: (EBIT + Depreciation)/Interest | B36: =('Income statement '!C9+'Income statement '!C8)/'Income statement '!C10 -> 7.212766 | C36: times | E36: The company has 7.21 times more cash than the interest they have to pay. They can pay up to 7.2 times the interest they have to pay with the cash and only cash not taking into consideration other assets to pay their interest. Way above the industry, good ratio | F36: Average on the industry 3.23 | G36: NYU | H36: Good
A38: III. Asset Utilization, or turnover, ratios
A40: Inventory turnover | E40: Definition: How many times a company has sold and replaced the inventory within a certain period of time. Usually one fiscal year
A41: Cost of goods sold/Inventory | B41: ='Income statement '!C7/'Balance Sheet'!D12 -> 3.1848341 | C41: times | E41: The company replaces the inventory 3.18 times over the year. Overstocking. The average on the industry is at 759 which makes P Corp very bad in this ratio since they take very long time to replace their inventory compared to their competitors | F41: Average on the industry 759 | G41: Ready Ratios | H41: Bad
A43: Days sales in inventory | E43: Definition: The time it takes to sell all the inventory
A44: 365 days/inventory turnover | B44: =365/B41 -> 114.60565 | C44: days | E44: Its takes 115 days to sell all the inventory. This one is corralated to inventory turnover. The average on the industry would be at 0.48 meaning that P Corp is too slow | F44: Average on the industry 0.48 | G44: Ready Ratios | H44: Bad
A46: Receivables turnover | E46: Definition: How often a company collects money that is owed to them from customer
A47: Sales/Accounts receivable | B47: ='Income statement '!C6/'Balance Sheet'!D11 -> 12.558511 | C47: times | E47: On average the company collects their accounts receivable 12.55 times per year. P Corp again is very slow to do this since their competitors are at very high-performance ratios on an average of 385 | F47: Average on the industry 385 | G47: Ready Ratios | H47: Bad
A49: Receivables period | E49: Definition: Time in days it takes to our customer to pay us
A50: 365 days/receivables turnover | B50: =365/B47 -> 29.063956 | C50: days | E50: Our customer took an average of 29 days to pay us. Again this one is correlated to the receivables turnover ratio and the receivables period is very slow since the average is at 0.94 | F50: Average on the industry 0.94 | G50: Ready Ratios | H50: Bad
A52: Operating cycle | E52: Definition:Time it takes to buy goods, sell them and receive the payment
A53: Inventory period + accounts receivable period | B53: =B44+B50 -> 143.66961 | C53: days | E53: On average it took us 144 days since the day we bought the inventory we sold it all and received the payment. Once again very bad ratio being very slow collecting because the average on the industry is at 1.42 | F53: Average on the industry 1.42 | G53: No link. I calculated myself summing F44 and F49 to get the average | H53: Bad
A55: Payables turnover | E55: Definition: How many times are paid our debts within a specific period of time. Usually a fiscal year
A56: Cost of goods sold/Accounts payable | B56: ='Income statement '!C7/'Balance Sheet'!D20 -> 3.9069767 | C56: times | E56: This means suppliers are paid 3.9 times a year. Good ratio between 8-10. | F56: Average between 8-10 | G56: Zycus | H56: Bad | I56: Could not find a breakdown of a table for each industry, however according to this source an ideal average would be from 8 to 10
A58: Payable period | E58: Definition: The avarege time it takes to pay our suppiers
A59: 365 days/payables turnover | B59: =365/B56 -> 93.422619 | C59: days | E59: It took us an average of 93 days to pay off our bills. This one correlates to payables turnover, therefore this one is bad too | F59: Average 35 to 45 | G59: Zycus | H59: Bad
A61: Cash cycle | E61: Definition: Time it takes to convert our investment into cash
A62: operating cycle - accounts payable period | B62: =B53-B59 -> 50.246992 | C62: days | E62: There is a 50 day delay since the day we pay for the merchandise to the time we collect the sale. P Corp again is slow here since the average on the marke is --33.58 and 44.58 which means that the inventory is sold before you have to pay for it | F62: Average between -33.58 and -44.58 | G62: No link. I calculated myself summing F53 and F59 to get the average | H62: Bad
A64: Total Asset turnover | E64: Definition: Efficiency of a company using their assets to produce sales
...
